<?xml version="1.0" ?>
<sdf version="1.5">
  <world name="default">
    <!-- A global light source -->
    <include>
      <uri>model://sun</uri>
    </include>
    <!-- A ground plane -->
    <include>
      <uri>model://ground_plane</uri>
    </include>

 
    <model name="my_robot">
 <static>false</static>
<link name='chassis'>
            <pose>0 0 .1 0 0 0</pose>

            <collision name='collision'>
              <geometry>
                <box>
                  <size>.4 .2 .1</size>
                </box>
              </geometry>
            </collision>

            <visual name='visual'>
      <geometry>
        <mesh>
          <uri>model://gazebo_models/pioneer2dx/meshes/chassis.dae</uri>
          <pose>0 0 0.05 0 0 0</pose>
          <scale>0.9 0.5 0.5</scale>
        </mesh>
      </geometry>
    </visual>
  <collision name='caster_collision'>
            <pose>-0.15 0 -0.05 0 0 0</pose>
            <geometry>
                <sphere>
                <radius>.05</radius>
              </sphere>
            </geometry>

            <surface>
              <friction>
                <ode>
                  <mu>0</mu>
                  <mu2>0</mu2>
                  <slip1>1.0</slip1>
                  <slip2>1.0</slip2>
                </ode>
              </friction>
            </surface>
          </collision>

          <visual name='caster_visual'>
            <pose>-0.15 0 -0.05 0 0 0</pose>
            <geometry>
              <sphere>
                <radius>.05</radius>
              </sphere>
            </geometry>
          </visual>
   </link>
  <link name="left_wheel">
        <pose>0.1 0.13 0.1 0 1.5707 1.5707</pose>
        <collision name="collision">
          <geometry>
            <cylinder>
              <radius>.1</radius>
              <length>.05</length>
            </cylinder>
          </geometry>
        </collision>
        <visual name="visual">
          <geometry>
            <cylinder>
              <radius>.1</radius>
              <length>.05</length>
            </cylinder>
          </geometry>
        </visual>
      </link>
   <link name="right_wheel">
        <pose>0.1 -0.13 0.1 0 1.5707 1.5707</pose>
        <collision name="collision">
          <geometry>
            <cylinder>
              <radius>.1</radius>
              <length>.05</length>
            </cylinder>
          </geometry>
        </collision>
        <visual name="visual">
          <geometry>
            <cylinder>
              <radius>.1</radius>
              <length>.05</length>
            </cylinder>
          </geometry>
        </visual>
      </link>
 <joint type="revolute" name="left_wheel_hinge">
        <pose>0 0 -0.03 0 0 0</pose>
        <child>left_wheel</child>
        <parent>chassis</parent>
        <axis>
          <xyz>0 1 0</xyz>
        </axis>
      </joint>

      <joint type="revolute" name="right_wheel_hinge">
        <pose>0 0 0.03 0 0 0</pose>
        <child>right_wheel</child>
        <parent>chassis</parent>
        <axis>
          <xyz>0 1 0</xyz>
        </axis>
      </joint>
      <include>
      <uri>model://hokuyo</uri>
      <pose>0.2 0 0.2 0 0 0</pose>
    </include>
    <joint name="hokuyo_joint" type="fixed">
      <child>hokuyo::link</child>
      <parent>chassis</parent>
      <plugin name="laser" filename="libgazebo_ros_laser.so"> <topicName>/hokuyo_laser</topicName> <frameName>map</frameName> </plugin>
    </joint>

    <plugin name="left_wheel_vel" filename="libleft_wheel_plugin.so">
        <velocity>5</velocity>
      </plugin>

      <plugin name="right_wheel_vel" filename="libright_wheel_plugin.so">
        <velocity>5</velocity>
      </plugin>
    
  </model>

  </world>
</sdf>
